<?xml version="1.0" ?>
<!-- Generated using onshape-to-robot -->
<!-- Onshape https://cad.onshape.com/documents/dd3abe9e9c2b991f8b4c543e/w/cd0ed4dbbed8ef5fec1acda2/e/cef9e1cc3745d261afba2600 -->
<robot name="fivebar_2dof">
  <link name="world"/>
  <!-- Link base_asm -->
  <link name="base_asm">
    <inertial>
      <origin xyz="-0 0.0131614 -2.75227e-05" rpy="0 0 0"/>
      <mass value="0.530155"/>
      <inertia ixx="0.000332831" ixy="0" ixz="-1.462e-09" iyy="0.0022674" iyz="-2.26825e-07" izz="0.00209532"/>
    </inertial>
    <!-- Part dual_motor_testbed_cover -->
    <visual>
      <origin xyz="0 0.032 -0.000174715" rpy="3.14159 -0 0"/>
      <geometry>
        <mesh filename="package://odri_dual_motor_testbed_description/meshes/assets/dual_motor_testbed_cover.stl"/>
      </geometry>
      <material name="dual_motor_testbed_cover_material">
        <color rgba="1 1 1 1"/>
      </material>
    </visual>
    <collision>
      <origin xyz="0 0.032 -0.000174715" rpy="3.14159 -0 0"/>
      <geometry>
        <mesh filename="package://odri_dual_motor_testbed_description/meshes/assets/dual_motor_testbed_cover.stl"/>
      </geometry>
    </collision>
    <!-- Part part_13 -->
    <visual>
      <origin xyz="0.065 0 -0.000174715" rpy="3.14159 -0 -0"/>
      <geometry>
        <mesh filename="package://odri_dual_motor_testbed_description/meshes/assets/part_13.stl"/>
      </geometry>
      <material name="part_13_material">
        <color rgba="0.376471 0.376471 0.376471 1"/>
      </material>
    </visual>
    <collision>
      <origin xyz="0.065 0 -0.000174715" rpy="3.14159 -0 -0"/>
      <geometry>
        <mesh filename="package://odri_dual_motor_testbed_description/meshes/assets/part_13.stl"/>
      </geometry>
    </collision>
    <!-- Part dual_motor_testbed_base -->
    <visual>
      <origin xyz="0 0.032 -6.31456e-06" rpy="3.14159 -0 -0"/>
      <geometry>
        <mesh filename="package://odri_dual_motor_testbed_description/meshes/assets/dual_motor_testbed_base.stl"/>
      </geometry>
      <material name="dual_motor_testbed_base_material">
        <color rgba="1 1 1 1"/>
      </material>
    </visual>
    <collision>
      <origin xyz="0 0.032 -6.31456e-06" rpy="3.14159 -0 -0"/>
      <geometry>
        <mesh filename="package://odri_dual_motor_testbed_description/meshes/assets/dual_motor_testbed_base.stl"/>
      </geometry>
    </collision>
    <!-- Part part_13_2 -->
    <visual>
      <origin xyz="-0.065 0 -0.000174715" rpy="3.14159 -0 -0"/>
      <geometry>
        <mesh filename="package://odri_dual_motor_testbed_description/meshes/assets/part_13.stl"/>
      </geometry>
      <material name="part_13_2_material">
        <color rgba="0.376471 0.376471 0.376471 1"/>
      </material>
    </visual>
    <collision>
      <origin xyz="-0.065 0 -0.000174715" rpy="3.14159 -0 -0"/>
      <geometry>
        <mesh filename="package://odri_dual_motor_testbed_description/meshes/assets/part_13.stl"/>
      </geometry>
    </collision>
  </link>
  
  <joint name="base_asm_in_world" type="fixed">
    <parent link="world" />
    <child link="base_asm" />
    <origin xyz="0.0 0.0 0.001" rpy ="0.0 0.0 0.0"/>
  </joint>
  
  <!-- Link rotor_asm -->
  <link name="rotor_asm">
    <inertial>
      <origin xyz="1.831e-09 7.07212e-05 -0.00543669" rpy="0 0 0"/>
      <mass value="0.0296045"/>
      <inertia ixx="7.98111e-06" ixy="0" ixz="-0" iyy="7.93749e-06" iyz="1.3052e-08" izz="1.11834e-05"/>
    </inertial>
    <!-- Part l1l -->
    <visual>
      <origin xyz="0 -0.04 -0.019" rpy="0 -0 1.5708"/>
      <geometry>
        <mesh filename="package://odri_dual_motor_testbed_description/meshes/assets/l1l.stl"/>
      </geometry>
      <material name="l1l_material">
        <color rgba="0.647059 0.647059 0.647059 1"/>
      </material>
    </visual>
    <collision>
      <origin xyz="0 -0.04 -0.019" rpy="0 -0 1.5708"/>
      <geometry>
        <mesh filename="package://odri_dual_motor_testbed_description/meshes/assets/l1l.stl"/>
      </geometry>
      <surface>
        <contact>
          <collide_bitmask>0x04</collide_bitmask>
        </contact>
      </surface>
    </collision>
    <!-- Part fastener_shcs_m3_6 -->
    <visual>
      <origin xyz="0 0.006 -0.011" rpy="3.14159 0 -0"/>
      <geometry>
        <mesh filename="package://odri_dual_motor_testbed_description/meshes/assets/fastener_shcs_m3_6.stl"/>
      </geometry>
      <material name="fastener_shcs_m3_6_material">
        <color rgba="0.407843 0.427451 0.486275 1"/>
      </material>
    </visual>
    <collision>
      <origin xyz="0 0.006 -0.011" rpy="3.14159 0 -0"/>
      <geometry>
        <mesh filename="package://odri_dual_motor_testbed_description/meshes/assets/fastener_shcs_m3_6.stl"/>
      </geometry>
    </collision>
    <!-- Part motor_antigravity_4004_custom_shaft -->
    <visual>
      <origin xyz="0 0 0.025" rpy="-3.14159 0 -0"/>
      <geometry>
        <mesh filename="package://odri_dual_motor_testbed_description/meshes/assets/motor_antigravity_4004_custom_shaft.stl"/>
      </geometry>
      <material name="motor_antigravity_4004_custom_shaft_material">
        <color rgba="0.568627 0.588235 0.666667 1"/>
      </material>
    </visual>
    <collision>
      <origin xyz="0 0 0.025" rpy="-3.14159 0 -0"/>
      <geometry>
        <mesh filename="package://odri_dual_motor_testbed_description/meshes/assets/motor_antigravity_4004_custom_shaft.stl"/>
      </geometry>
    </collision>
    <!-- Part hand_wheel -->
    <visual>
      <origin xyz="0 0 -0.008" rpy="-1.5708 0 -0"/>
      <geometry>
        <mesh filename="package://odri_dual_motor_testbed_description/meshes/assets/hand_wheel.stl"/>
      </geometry>
      <material name="hand_wheel_material">
        <color rgba="0.768627 0.768627 0.768627 1"/>
      </material>
    </visual>
    <collision>
      <origin xyz="0 0 -0.008" rpy="-1.5708 0 -0"/>
      <geometry>
        <mesh filename="package://odri_dual_motor_testbed_description/meshes/assets/hand_wheel.stl"/>
      </geometry>
    </collision>
    <!-- Part fastener_shcs_m3_6_2 -->
    <visual>
      <origin xyz="0.006 0 -0.011" rpy="-3.14159 0 -0"/>
      <geometry>
        <mesh filename="package://odri_dual_motor_testbed_description/meshes/assets/fastener_shcs_m3_6.stl"/>
      </geometry>
      <material name="fastener_shcs_m3_6_2_material">
        <color rgba="0.407843 0.427451 0.486275 1"/>
      </material>
    </visual>
    <collision>
      <origin xyz="0.006 0 -0.011" rpy="-3.14159 0 -0"/>
      <geometry>
        <mesh filename="package://odri_dual_motor_testbed_description/meshes/assets/fastener_shcs_m3_6.stl"/>
      </geometry>
    </collision>
    <!-- Part fastener_shcs_m3_6_3 -->
    <visual>
      <origin xyz="-0.006 0 -0.011" rpy="-3.14159 0 -0"/>
      <geometry>
        <mesh filename="package://odri_dual_motor_testbed_description/meshes/assets/fastener_shcs_m3_6.stl"/>
      </geometry>
      <material name="fastener_shcs_m3_6_3_material">
        <color rgba="0.407843 0.427451 0.486275 1"/>
      </material>
    </visual>
    <collision>
      <origin xyz="-0.006 0 -0.011" rpy="-3.14159 0 -0"/>
      <geometry>
        <mesh filename="package://odri_dual_motor_testbed_description/meshes/assets/fastener_shcs_m3_6.stl"/>
      </geometry>
    </collision>
    <!-- Part fastener_shcs_m3_6_4 -->
    <visual>
      <origin xyz="0 -0.006 -0.011" rpy="-3.14159 0 -0"/>
      <geometry>
        <mesh filename="package://odri_dual_motor_testbed_description/meshes/assets/fastener_shcs_m3_6.stl"/>
      </geometry>
      <material name="fastener_shcs_m3_6_4_material">
        <color rgba="0.407843 0.427451 0.486275 1"/>
      </material>
    </visual>
    <collision>
      <origin xyz="0 -0.006 -0.011" rpy="-3.14159 0 -0"/>
      <geometry>
        <mesh filename="package://odri_dual_motor_testbed_description/meshes/assets/fastener_shcs_m3_6.stl"/>
      </geometry>
    </collision>
    <!-- Part motor_antigravity_4004_rotor -->
    <visual>
      <origin xyz="0 0 -0.008" rpy="-1.5708 -0 0.785398"/>
      <geometry>
        <mesh filename="package://odri_dual_motor_testbed_description/meshes/assets/motor_antigravity_4004_rotor.stl"/>
      </geometry>
      <material name="motor_antigravity_4004_rotor_material">
        <color rgba="0.501961 0.501961 0.501961 1"/>
      </material>
    </visual>
    <collision>
      <origin xyz="0 0 -0.008" rpy="-1.5708 -0 0.785398"/>
      <geometry>
        <mesh filename="package://odri_dual_motor_testbed_description/meshes/assets/motor_antigravity_4004_rotor.stl"/>
      </geometry>
    </collision>
  </link>
  <!-- Link l2r -->
  <link name="l2r">
    <inertial>
      <origin xyz="0 0 0" rpy="0 0 0"/>
      <mass value="0.01"/>
      <inertia ixx="1e-05" ixy="0" ixz="0" iyy="1e-05" iyz="0" izz="1e-05"/>
    </inertial>
    <!-- Part l2r -->
    <visual>
      <origin xyz="0 0.06 0.005" rpy="-3.14159 0 -0"/>
      <geometry>
        <mesh filename="package://odri_dual_motor_testbed_description/meshes/assets/l2r.stl"/>
      </geometry>
      <material name="l2r_material">
        <color rgba="0.231373 0.380392 0.705882 1"/>
      </material>
    </visual>
    <collision>
      <origin xyz="0 0.06 0.005" rpy="-3.14159 0 -0"/>
      <geometry>
        <mesh filename="package://odri_dual_motor_testbed_description/meshes/assets/l2r.stl"/>
      </geometry>
      <surface>
        <contact>
          <collide_bitmask>0x01</collide_bitmask>
        </contact>
      </surface>
    </collision>
  </link>
  <!-- Frame closing_ee_1 (dummy link + fixed joint) -->
  <link name="closing_ee_1">
    <origin xyz="0 0 0" rpy="0 -0 0"/>
    <inertial>
      <origin xyz="0 0 0" rpy="0 0 0"/>
      <mass value="1e-9"/>
      <inertia ixx="0" ixy="0" ixz="0" iyy="0" iyz="0" izz="0"/>
    </inertial>
  </link>
  <joint name="closing_ee_1_frame" type="fixed">
    <origin xyz="0 -0.125 -0.002" rpy="-3.14159 0 -0"/>
    <parent link="l2r"/>
    <child link="closing_ee_1"/>
    <axis xyz="0 0 0"/>
  </joint>
  <!-- Joint from rotor_asm to l2r -->
  <joint name="elbowL" type="revolute">
    <origin xyz="-0.06 0 -0.014" rpy="3.14159 0 -2.6769"/>
    <parent link="rotor_asm"/>
    <child link="l2r"/>
    <axis xyz="0 0 1"/>
    <limit effort="1" velocity="1" lower="-3.141592653589793" upper="3.141592653589793"/>
  </joint>
  <!-- Joint from base_asm to rotor_asm -->
  <joint name="motorL" type="revolute">
    <origin xyz="-0.065 -0.0112 -0.000174715" rpy="-1.5708 -0 -0"/>
    <parent link="base_asm"/>
    <child link="rotor_asm"/>
    <axis xyz="0 0 1"/>
    <limit effort="1" velocity="1" lower="-3.141592653589793" upper="3.141592653589793"/>
  </joint>
  <!-- Link rotor_asm_2 -->
  <link name="rotor_asm_2">
    <inertial>
      <origin xyz="5.00087e-05 5.00061e-05 -0.00543669" rpy="0 0 0"/>
      <mass value="0.0296045"/>
      <inertia ixx="7.9593e-06" ixy="-2.1811e-08" ixz="9.229e-09" iyy="7.9593e-06" iyz="9.229e-09" izz="1.11834e-05"/>
    </inertial>
    <!-- Part l1r -->
    <visual>
      <origin xyz="-0 -0 -0.019" rpy="-0 0 0.785398"/>
      <geometry>
        <mesh filename="package://odri_dual_motor_testbed_description/meshes/assets/l1r.stl"/>
      </geometry>
      <material name="l1r_material">
        <color rgba="0.647059 0.647059 0.647059 1"/>
      </material>
    </visual>
    <collision>
      <origin xyz="-0 -0 -0.019" rpy="-0 0 0.785398"/>
      <geometry>
        <mesh filename="package://odri_dual_motor_testbed_description/meshes/assets/l1r.stl"/>
      </geometry>
      <surface>
        <contact>
          <collide_bitmask>0x08</collide_bitmask>
        </contact>
      </surface>

    </collision>
    <!-- Part fastener_shcs_m3_6_5 -->
    <visual>
      <origin xyz="0.00424264 0.00424264 -0.011" rpy="3.14159 0 -0.785398"/>
      <geometry>
        <mesh filename="package://odri_dual_motor_testbed_description/meshes/assets/fastener_shcs_m3_6.stl"/>
      </geometry>
      <material name="fastener_shcs_m3_6_5_material">
        <color rgba="0.407843 0.427451 0.486275 1"/>
      </material>
    </visual>
    <collision>
      <origin xyz="0.00424264 0.00424264 -0.011" rpy="3.14159 0 -0.785398"/>
      <geometry>
        <mesh filename="package://odri_dual_motor_testbed_description/meshes/assets/fastener_shcs_m3_6.stl"/>
      </geometry>
    </collision>
    <!-- Part motor_antigravity_4004_custom_shaft_2 -->
    <visual>
      <origin xyz="-0 -0 0.025" rpy="-3.14159 0 -0.785398"/>
      <geometry>
        <mesh filename="package://odri_dual_motor_testbed_description/meshes/assets/motor_antigravity_4004_custom_shaft.stl"/>
      </geometry>
      <material name="motor_antigravity_4004_custom_shaft_2_material">
        <color rgba="0.568627 0.588235 0.666667 1"/>
      </material>
    </visual>
    <collision>
      <origin xyz="-0 -0 0.025" rpy="-3.14159 0 -0.785398"/>
      <geometry>
        <mesh filename="package://odri_dual_motor_testbed_description/meshes/assets/motor_antigravity_4004_custom_shaft.stl"/>
      </geometry>
    </collision>
    <!-- Part hand_wheel_2 -->
    <visual>
      <origin xyz="-0 -0 -0.008" rpy="-1.5708 -0 -0.785398"/>
      <geometry>
        <mesh filename="package://odri_dual_motor_testbed_description/meshes/assets/hand_wheel.stl"/>
      </geometry>
      <material name="hand_wheel_2_material">
        <color rgba="0.768627 0.768627 0.768627 1"/>
      </material>
    </visual>
    <collision>
      <origin xyz="-0 -0 -0.008" rpy="-1.5708 -0 -0.785398"/>
      <geometry>
        <mesh filename="package://odri_dual_motor_testbed_description/meshes/assets/hand_wheel.stl"/>
      </geometry>
    </collision>
    <!-- Part fastener_shcs_m3_6_6 -->
    <visual>
      <origin xyz="0.00424264 -0.00424264 -0.011" rpy="-3.14159 0 -0.785398"/>
      <geometry>
        <mesh filename="package://odri_dual_motor_testbed_description/meshes/assets/fastener_shcs_m3_6.stl"/>
      </geometry>
      <material name="fastener_shcs_m3_6_6_material">
        <color rgba="0.407843 0.427451 0.486275 1"/>
      </material>
    </visual>
    <collision>
      <origin xyz="0.00424264 -0.00424264 -0.011" rpy="-3.14159 0 -0.785398"/>
      <geometry>
        <mesh filename="package://odri_dual_motor_testbed_description/meshes/assets/fastener_shcs_m3_6.stl"/>
      </geometry>
    </collision>
    <!-- Part fastener_shcs_m3_6_7 -->
    <visual>
      <origin xyz="-0.00424264 0.00424264 -0.011" rpy="-3.14159 0 -0.785398"/>
      <geometry>
        <mesh filename="package://odri_dual_motor_testbed_description/meshes/assets/fastener_shcs_m3_6.stl"/>
      </geometry>
      <material name="fastener_shcs_m3_6_7_material">
        <color rgba="0.407843 0.427451 0.486275 1"/>
      </material>
    </visual>
    <collision>
      <origin xyz="-0.00424264 0.00424264 -0.011" rpy="-3.14159 0 -0.785398"/>
      <geometry>
        <mesh filename="package://odri_dual_motor_testbed_description/meshes/assets/fastener_shcs_m3_6.stl"/>
      </geometry>
    </collision>
    <!-- Part fastener_shcs_m3_6_8 -->
    <visual>
      <origin xyz="-0.00424264 -0.00424264 -0.011" rpy="-3.14159 0 -0.785398"/>
      <geometry>
        <mesh filename="package://odri_dual_motor_testbed_description/meshes/assets/fastener_shcs_m3_6.stl"/>
      </geometry>
      <material name="fastener_shcs_m3_6_8_material">
        <color rgba="0.407843 0.427451 0.486275 1"/>
      </material>
    </visual>
    <collision>
      <origin xyz="-0.00424264 -0.00424264 -0.011" rpy="-3.14159 0 -0.785398"/>
      <geometry>
        <mesh filename="package://odri_dual_motor_testbed_description/meshes/assets/fastener_shcs_m3_6.stl"/>
      </geometry>
    </collision>
    <!-- Part motor_antigravity_4004_rotor_2 -->
    <visual>
      <origin xyz="-0 -0 -0.008" rpy="-1.5708 0 -0"/>
      <geometry>
        <mesh filename="package://odri_dual_motor_testbed_description/meshes/assets/motor_antigravity_4004_rotor.stl"/>
      </geometry>
      <material name="motor_antigravity_4004_rotor_2_material">
        <color rgba="0.501961 0.501961 0.501961 1"/>
      </material>
    </visual>
    <collision>
      <origin xyz="-0 -0 -0.008" rpy="-1.5708 0 -0"/>
      <geometry>
        <mesh filename="package://odri_dual_motor_testbed_description/meshes/assets/motor_antigravity_4004_rotor.stl"/>
      </geometry>
    </collision>
  </link>
  <!-- Link l2l -->
  <link name="l2l">
    <inertial>
      <origin xyz="0 0 0" rpy="0 0 0"/>
      <mass value="0.01"/>
      <inertia ixx="1e-05" ixy="0" ixz="0" iyy="1e-05" iyz="0" izz="1e-05"/>
    </inertial>
    <!-- Part l2l -->
    <visual>
      <origin xyz="-0.04 0.06 0.005" rpy="-3.14159 -0 -0"/>
      <geometry>
        <mesh filename="package://odri_dual_motor_testbed_description/meshes/assets/l2l.stl"/>
      </geometry>
      <material name="l2l_material">
        <color rgba="0.231373 0.380392 0.705882 1"/>
      </material>
    </visual>
    <collision>
      <origin xyz="-0.04 0.06 0.005" rpy="-3.14159 -0 -0"/>
      <geometry>
        <mesh filename="package://odri_dual_motor_testbed_description/meshes/assets/l2l.stl"/>
      </geometry>

      <surface>
        <contact>
          <collide_bitmask>0x02</collide_bitmask>
        </contact>
      </surface>

    </collision>
  </link>
  <!-- Frame closing_ee_2 (dummy link + fixed joint) -->
  <link name="closing_ee_2">
    <origin xyz="0 0 0" rpy="0 -0 0"/>
    <inertial>
      <origin xyz="0 0 0" rpy="0 0 0"/>
      <mass value="1e-9"/>
      <inertia ixx="0" ixy="0" ixz="0" iyy="0" iyz="0" izz="0"/>
    </inertial>
  </link>
  <joint name="closing_ee_2_frame" type="fixed">
    <origin xyz="0 -0.125 -0.0015" rpy="-3.14159 0 -1.5708"/>
    <parent link="l2l"/>
    <child link="closing_ee_2"/>
    <axis xyz="0 0 0"/>
  </joint>
  <!-- Joint from rotor_asm_2 to l2l -->
  <joint name="elbowR" type="revolute">
    <origin xyz="-0.0424264 0.0424264 -0.014" rpy="-3.14159 0 0.0589597"/>
    <parent link="rotor_asm_2"/>
    <child link="l2l"/>
    <axis xyz="0 0 1"/>
    <limit effort="1" velocity="1" lower="-3.141592653589793" upper="3.141592653589793"/>
  </joint>
  <!-- Joint from base_asm to rotor_asm_2 -->
  <joint name="motorR" type="revolute">
    <origin xyz="0.065 -0.0112 -0.000174715" rpy="1.5708 1.16507 -3.14159"/>
    <parent link="base_asm"/>
    <child link="rotor_asm_2"/>
    <axis xyz="0 0 1"/>
    <limit effort="1" velocity="1" lower="-3.141592653589793" upper="3.141592653589793"/>
  </joint>


  <ros2_control name="GazeboOdriSimSystem" type="system">
    <hardware>
      <plugin>odri_gz_ros2_control/GazeboOdriSimSystem</plugin>
    </hardware>
    <joint name="motorL">
      <command_interface name="position" />
      <command_interface name="velocity" />
      <command_interface name="effort" />
      <command_interface name="gain_kp" />
      <command_interface name="gain_kd" />
      <state_interface name="velocity" />
      <state_interface name="position" />
      <state_interface name="effort" />
    </joint>
    <joint name="motorR">
      <command_interface name="position" />
      <command_interface name="velocity" />
      <command_interface name="effort" />
      <command_interface name="gain_kp" />
      <command_interface name="gain_kd" />
      <state_interface name="velocity" />
      <state_interface name="position" />
      <state_interface name="effort" />
    </joint>

    <joint name="elbowL">
      <state_interface name="velocity" />
      <state_interface name="position" />
      <state_interface name="effort" />
    </joint>

    <joint name="elbowR">
      <state_interface name="velocity" />
      <state_interface name="position" />
      <state_interface name="effort" />
    </joint>
    
  </ros2_control>

  <gazebo>
    <plugin filename="odri_gz_ros2_control-system" name="odri_gz_ros2_control::GazeboOdriSimROS2ControlPlugin">
      <parameters>$(find odri_dual_motor_testbed_gazebo)/config/forward_command_controller.yaml</parameters>
    </plugin>
  </gazebo>
  
  <!-- ================================================================ -->
  <!--      Gazebo Harmonic (gz-sim8) system plugin for five-bar loop closure. -->
  <!--      Exact direct geometric model: reads motorL/motorR and imposes -->
  <!--      elbowL/elbowR via Joint::ResetPosition every step. -->
  <!--      See five_bar_mgd_spec.md at the repository root. -->
  <!--      ================================================================ -->
  <gazebo>
    <plugin filename="libFiveBarClosurePlugin.so"
            name="odri_gz::FiveBarClosurePlugin">
      <!-- Actuated joints (inputs, theta1/theta2). -->
      <motor_joint1>motorL</motor_joint1>
      <motor_joint2>motorR</motor_joint2>
      <!-- Passive joints (outputs, beta1/beta2), imposed exactly. -->
      <elbow_joint1>elbowL</elbow_joint1>
      <elbow_joint2>elbowR</elbow_joint2>
      <!-- Geometry parameters (verified numerically, see
           five_bar_mgd_spec.md section 2). -->
      <a_x>-0.065</a_x>
      <a_z>0</a_z>
      <b_x>0.065</b_x>
      <b_z>0</b_z>
      <l1>0.06</l1>
      <l2>0.125</l2>
      <phi1>3.14159265358979323846</phi1>
      <phi2>1.9504681943696776</phi2>
      <psi1>1.1061036468685321</psi1>
      <psi2>2.6769066384729094</psi2>
    </plugin>
  </gazebo>

</robot>
